<?xml version="1.0"?>
<robot name="ohd_2">
  <material name="face_material">
    <color rgba="0.8 0.8 0.8 1.0"/>
  </material>
  <link name="face_0">
    <visual>
      <geometry>
        <mesh filename="meshes/face_0.stl" scale="1.0 1.0 1.0"/>
      </geometry>
      <material name="face_material"/>
    </visual>
  </link>
  <link name="face_1">
    <visual>
      <geometry>
        <mesh filename="meshes/face_1.stl" scale="1.0 1.0 1.0"/>
      </geometry>
      <material name="face_material"/>
    </visual>
  </link>
  <link name="face_2">
    <visual>
      <geometry>
        <mesh filename="meshes/face_2.stl" scale="1.0 1.0 1.0"/>
      </geometry>
      <material name="face_material"/>
    </visual>
  </link>
  <link name="face_3">
    <visual>
      <geometry>
        <mesh filename="meshes/face_3.stl" scale="1.0 1.0 1.0"/>
      </geometry>
      <material name="face_material"/>
    </visual>
  </link>
  <link name="face_4">
    <visual>
      <geometry>
        <mesh filename="meshes/face_4.stl" scale="1.0 1.0 1.0"/>
      </geometry>
      <material name="face_material"/>
    </visual>
  </link>
  <link name="face_5">
    <visual>
      <geometry>
        <mesh filename="meshes/face_5.stl" scale="1.0 1.0 1.0"/>
      </geometry>
      <material name="face_material"/>
    </visual>
  </link>
  <link name="face_6">
    <visual>
      <geometry>
        <mesh filename="meshes/face_6.stl" scale="1.0 1.0 1.0"/>
      </geometry>
      <material name="face_material"/>
    </visual>
  </link>
  <joint name="joint_0" type="revolute">
    <parent link="face_0"/>
    <child link="face_3"/>
    <origin xyz="15.000000 0.000000 0.000000" rpy="0 0 0"/>
    <axis xyz="-1.000000 -0.000000 0.000000"/>
    <limit effort="10" velocity="3.14" lower="-1.57" upper="1.57"/>
  </joint>
  <joint name="joint_1" type="revolute">
    <parent link="face_0"/>
    <child link="face_2"/>
    <origin xyz="15.000000 100.000000 0.000000" rpy="0 0 0"/>
    <axis xyz="1.000000 0.000000 0.000000"/>
    <limit effort="10" velocity="3.14" lower="-1.57" upper="1.57"/>
  </joint>
  <joint name="joint_2" type="revolute">
    <parent link="face_0"/>
    <child link="face_1"/>
    <origin xyz="85.000000 100.000000 0.000000" rpy="0 0 0"/>
    <axis xyz="1.000000 0.000000 0.000000"/>
    <limit effort="10" velocity="3.14" lower="-1.57" upper="1.57"/>
  </joint>
  <joint name="joint_3" type="revolute">
    <parent link="face_1"/>
    <child link="face_5"/>
    <origin xyz="0.000000 45.000000 0.000000" rpy="0 0 0"/>
    <axis xyz="1.000000 0.000000 0.000000"/>
    <limit effort="10" velocity="3.14" lower="-1.57" upper="1.57"/>
  </joint>
  <joint name="joint_4" type="revolute">
    <parent link="face_2"/>
    <child link="face_4"/>
    <origin xyz="0.000000 45.000000 0.000000" rpy="0 0 0"/>
    <axis xyz="1.000000 0.000000 0.000000"/>
    <limit effort="10" velocity="3.14" lower="-1.57" upper="1.57"/>
  </joint>
  <joint name="joint_5" type="revolute">
    <parent link="face_3"/>
    <child link="face_6"/>
    <origin xyz="0.000000 -45.000000 0.000000" rpy="0 0 0"/>
    <axis xyz="-1.000000 -0.000000 0.000000"/>
    <limit effort="10" velocity="3.14" lower="-1.57" upper="1.57"/>
  </joint>
</robot>